Traceback (most recent call last):
  File "/usr/local/lib/python3.4/dist-packages/tensorflow/python/framework/common_shapes.py", line 594, in call_cpp_shape_fn
    status)
  File "/usr/lib/python3.4/contextlib.py", line 66, in __exit__
    next(self.gen)
  File "/usr/local/lib/python3.4/dist-packages/tensorflow/python/framework/errors.py", line 463, in raise_exception_on_not_ok_status
    pywrap_tensorflow.TF_GetCode(status))
tensorflow.python.framework.errors.InvalidArgumentError: Negative dimension size caused by subtracting 2 from 1

During handling of the above exception, another exception occurred:

Traceback (most recent call last):
  File "cnn_classify_cifar10.py", line 74, in <module>
    model.add(Lay.MaxPooling2D((2,2)))
  File "/usr/local/lib/python3.4/dist-packages/Keras-1.1.0-py3.4.egg/keras/models.py", line 308, in add
    output_tensor = layer(self.outputs[0])
  File "/usr/local/lib/python3.4/dist-packages/Keras-1.1.0-py3.4.egg/keras/engine/topology.py", line 514, in __call__
    self.add_inbound_node(inbound_layers, node_indices, tensor_indices)
  File "/usr/local/lib/python3.4/dist-packages/Keras-1.1.0-py3.4.egg/keras/engine/topology.py", line 572, in add_inbound_node
    Node.create_node(self, inbound_layers, node_indices, tensor_indices)
  File "/usr/local/lib/python3.4/dist-packages/Keras-1.1.0-py3.4.egg/keras/engine/topology.py", line 149, in create_node
    output_tensors = to_list(outbound_layer.call(input_tensors[0], mask=input_masks[0]))
  File "/usr/local/lib/python3.4/dist-packages/Keras-1.1.0-py3.4.egg/keras/layers/pooling.py", line 162, in call
    dim_ordering=self.dim_ordering)
  File "/usr/local/lib/python3.4/dist-packages/Keras-1.1.0-py3.4.egg/keras/layers/pooling.py", line 212, in _pooling_function
    border_mode, dim_ordering, pool_mode='max')
  File "/usr/local/lib/python3.4/dist-packages/Keras-1.1.0-py3.4.egg/keras/backend/tensorflow_backend.py", line 1761, in pool2d
    x = tf.nn.max_pool(x, pool_size, strides, padding=padding)
  File "/usr/local/lib/python3.4/dist-packages/tensorflow/python/ops/nn_ops.py", line 850, in max_pool
    name=name)
  File "/usr/local/lib/python3.4/dist-packages/tensorflow/python/ops/gen_nn_ops.py", line 1440, in _max_pool
    data_format=data_format, name=name)
  File "/usr/local/lib/python3.4/dist-packages/tensorflow/python/framework/op_def_library.py", line 749, in apply_op
    op_def=op_def)
  File "/usr/local/lib/python3.4/dist-packages/tensorflow/python/framework/ops.py", line 2382, in create_op
    set_shapes_for_outputs(ret)
  File "/usr/local/lib/python3.4/dist-packages/tensorflow/python/framework/ops.py", line 1783, in set_shapes_for_outputs
    shapes = shape_func(op)
  File "/usr/local/lib/python3.4/dist-packages/tensorflow/python/framework/common_shapes.py", line 596, in call_cpp_shape_fn
    raise ValueError(err.message)
ValueError: Negative dimension size caused by subtracting 2 from 1
