I tensorflow/stream_executor/dso_loader.cc:111] successfully opened CUDA library libcublas.so locally
I tensorflow/stream_executor/dso_loader.cc:111] successfully opened CUDA library libcudnn.so.5 locally
I tensorflow/stream_executor/dso_loader.cc:111] successfully opened CUDA library libcufft.so locally
I tensorflow/stream_executor/dso_loader.cc:111] successfully opened CUDA library libcuda.so.1 locally
I tensorflow/stream_executor/dso_loader.cc:111] successfully opened CUDA library libcurand.so locally
E tensorflow/stream_executor/cuda/cuda_driver.cc:491] failed call to cuInit: CUDA_ERROR_NO_DEVICE
I tensorflow/stream_executor/cuda/cuda_diagnostics.cc:153] retrieving CUDA diagnostic information for host: dlvc
I tensorflow/stream_executor/cuda/cuda_diagnostics.cc:160] hostname: dlvc
I tensorflow/stream_executor/cuda/cuda_diagnostics.cc:185] libcuda reported version is: 367.57.0
I tensorflow/stream_executor/cuda/cuda_diagnostics.cc:356] driver version file contents: """NVRM version: NVIDIA UNIX x86_64 Kernel Module  367.57  Mon Oct  3 20:37:01 PDT 2016
GCC version:  gcc version 5.4.0 20160609 (Ubuntu 5.4.0-6ubuntu1~16.04.2) 
"""
I tensorflow/stream_executor/cuda/cuda_diagnostics.cc:189] kernel reported version is: 367.57.0
I tensorflow/stream_executor/cuda/cuda_diagnostics.cc:293] kernel version seems to match DSO: 367.57.0
Using TensorFlow backend.
Exception ignored in: <bound method Session.__del__ of <tensorflow.python.client.session.Session object at 0x7fa5e1905550>>
Traceback (most recent call last):
  File "/usr/local/lib/python3.4/dist-packages/tensorflow/python/client/session.py", line 532, in __del__
AttributeError: 'NoneType' object has no attribute 'TF_DeleteStatus'
